<?xml version="1.0" encoding="UTF-8"?>
<!-- Generated by org.testng.reporters.JUnitReportReporter -->
<testsuite skipped="0" hostname="SILICUS508" name="com.mycompany.demoqt.testscripts.TestLogin" tests="5" failures="1" timestamp="31 May 2017 10:39:03 GMT" time="56.659" errors="0">
  <testcase name="testInvalidRecoverPassword" time="11.314" classname="com.mycompany.demoqt.testscripts.TestLogin"/>
  <testcase name="testLoginPageIsDisplayed" time="8.044" classname="com.mycompany.demoqt.testscripts.TestLogin">
    <failure type="java.lang.AssertionError" message="expected [CUSTOMER LOGIN] but found [CUSTOMER LOGIN.]">
      <![CDATA[java.lang.AssertionError: expected [CUSTOMER LOGIN] but found [CUSTOMER LOGIN.]
	at org.testng.Assert.fail(Assert.java:93)
	at org.testng.Assert.failNotEquals(Assert.java:512)
	at org.testng.Assert.assertEqualsImpl(Assert.java:134)
	at org.testng.Assert.assertEquals(Assert.java:115)
	at org.testng.Assert.assertEquals(Assert.java:189)
	at org.testng.Assert.assertEquals(Assert.java:199)
	at com.mycompany.demoqt.testscripts.TestLogin.testLoginPageIsDisplayed(TestLogin.java:36)
	at sun.reflect.NativeMethodAccessorImpl.invoke0(Native Method)
	at sun.reflect.NativeMethodAccessorImpl.invoke(Unknown Source)
	at sun.reflect.DelegatingMethodAccessorImpl.invoke(Unknown Source)
	at java.lang.reflect.Method.invoke(Unknown Source)
	at org.testng.internal.MethodInvocationHelper.invokeMethod(MethodInvocationHelper.java:108)
	at org.testng.internal.Invoker.invokeMethod(Invoker.java:661)
	at org.testng.internal.Invoker.invokeTestMethod(Invoker.java:869)
	at org.testng.internal.Invoker.invokeTestMethods(Invoker.java:1193)
	at org.testng.internal.TestMethodWorker.invokeTestMethods(TestMethodWorker.java:126)
	at org.testng.internal.TestMethodWorker.run(TestMethodWorker.java:109)
	at org.testng.TestRunner.privateRun(TestRunner.java:744)
	at org.testng.TestRunner.run(TestRunner.java:602)
	at org.testng.SuiteRunner.runTest(SuiteRunner.java:380)
	at org.testng.SuiteRunner.runSequentially(SuiteRunner.java:375)
	at org.testng.SuiteRunner.privateRun(SuiteRunner.java:340)
	at org.testng.SuiteRunner.run(SuiteRunner.java:289)
	at org.testng.SuiteRunnerWorker.runSuite(SuiteRunnerWorker.java:52)
	at org.testng.SuiteRunnerWorker.run(SuiteRunnerWorker.java:86)
	at org.testng.TestNG.runSuitesSequentially(TestNG.java:1301)
	at org.testng.TestNG.runSuitesLocally(TestNG.java:1226)
	at org.testng.TestNG.runSuites(TestNG.java:1144)
	at org.testng.TestNG.run(TestNG.java:1115)
	at org.testng.remote.AbstractRemoteTestNG.run(AbstractRemoteTestNG.java:126)
	at org.testng.remote.RemoteTestNG.initAndRun(RemoteTestNG.java:152)
	at org.testng.remote.RemoteTestNG.main(RemoteTestNG.java:57)
]]>
    </failure>
  </testcase> <!-- testLoginPageIsDisplayed -->
  <testcase name="testFieldValidation" time="12.049" classname="com.mycompany.demoqt.testscripts.TestLogin"/>
  <testcase name="testValidRecoverPassword" time="11.692" classname="com.mycompany.demoqt.testscripts.TestLogin"/>
  <testcase name="testLogIn" time="13.560" classname="com.mycompany.demoqt.testscripts.TestLogin"/>
</testsuite> <!-- com.mycompany.demoqt.testscripts.TestLogin -->
